{
  "start_time": 1755686348.6460326,
  "mode": "full",
  "version": "4.0.0",
  "enhanced_analysis": {
    "success": false,
    "output": "",
    "errors": "/mnt/SSD/PYCHARMPRODJECT/BOT_AI_V3/venv/bin/python3: can't open file '/mnt/SSD/PYCHARMPRODJECT/BOT_AI_V3/scripts/enhanced_master_test_runner.py': [Errno 2] No such file or directory\n",
    "duration": "enhanced_system"
  },
  "test_generation": {
    "success": false,
    "output": "",
    "errors": "/mnt/SSD/PYCHARMPRODJECT/BOT_AI_V3/venv/bin/python3: can't open file '/mnt/SSD/PYCHARMPRODJECT/BOT_AI_V3/scripts/comprehensive_test_generator.py': [Errno 2] No such file or directory\n",
    "tests_generated": true
  },
  "pytest_results": {
    "success": false,
    "output": "============================= test session starts ==============================\nplatform linux -- Python 3.12.3, pytest-8.4.1, pluggy-1.6.0 -- /mnt/SSD/PYCHARMPRODJECT/BOT_AI_V3/venv/bin/python3\ncachedir: .pytest_cache\nrootdir: /mnt/SSD/PYCHARMPRODJECT/BOT_AI_V3\nconfigfile: pytest.ini\nplugins: cov-6.2.1, anyio-4.9.0, asyncio-1.1.0\nasyncio: mode=Mode.AUTO, asyncio_default_fixture_loop_scope=None, asyncio_default_test_loop_scope=function\ncollecting ... collected 22 items / 3 errors\nrun-last-failure: None\n\n==================================== ERRORS ====================================\n_______ ERROR collecting tests/analysis/test_code_analyzer_validation.py _______\nImportError while importing test module '/mnt/SSD/PYCHARMPRODJECT/BOT_AI_V3/tests/analysis/test_code_analyzer_validation.py'.\nHint: make sure your test modules/packages have valid Python names.\nTraceback:\nvenv/lib/python3.12/site-packages/_pytest/python.py:498: in importtestmodule\n    mod = import_path(\nvenv/lib/python3.12/site-packages/_pytest/pathlib.py:587: in import_path\n    importlib.import_module(module_name)\n/usr/lib/python3.12/importlib/__init__.py:90: in import_module\n    return _bootstrap._gcd_import(name[level:], package, level)\n           ^^^^^^^^^^^^^^^^^^^^^^^^^^^^^^^^^^^^^^^^^^^^^^^^^^^^\n<frozen importlib._bootstrap>:1387: in _gcd_import\n    ???\n<frozen importlib._bootstrap>:1360: in _find_and_load\n    ???\n<frozen importlib._bootstrap>:1331: in _find_and_load_unlocked\n    ???\n<frozen importlib._bootstrap>:935: in _load_unlocked\n    ???\nvenv/lib/python3.12/site-packages/_pytest/assertion/rewrite.py:186: in exec_module\n    exec(co, module.__dict__)\ntests/analysis/test_code_analyzer_validation.py:15: in <module>\n    from scripts.run_code_usage_analysis import CodeUsageAnalyzer\nE   ModuleNotFoundError: No module named 'scripts.run_code_usage_analysis'\n_________ ERROR collecting tests/analysis/test_code_usage_analyzer.py __________\nImportError while importing test module '/mnt/SSD/PYCHARMPRODJECT/BOT_AI_V3/tests/analysis/test_code_usage_analyzer.py'.\nHint: make sure your test modules/packages have valid Python names.\nTraceback:\nvenv/lib/python3.12/site-packages/_pytest/python.py:498: in importtestmodule\n    mod = import_path(\nvenv/lib/python3.12/site-packages/_pytest/pathlib.py:587: in import_path\n    importlib.import_module(module_name)\n/usr/lib/python3.12/importlib/__init__.py:90: in import_module\n    return _bootstrap._gcd_import(name[level:], package, level)\n           ^^^^^^^^^^^^^^^^^^^^^^^^^^^^^^^^^^^^^^^^^^^^^^^^^^^^\n<frozen importlib._bootstrap>:1387: in _gcd_import\n    ???\n<frozen importlib._bootstrap>:1360: in _find_and_load\n    ???\n<frozen importlib._bootstrap>:1331: in _find_and_load_unlocked\n    ???\n<frozen importlib._bootstrap>:935: in _load_unlocked\n    ???\nvenv/lib/python3.12/site-packages/_pytest/assertion/rewrite.py:186: in exec_module\n    exec(co, module.__dict__)\ntests/analysis/test_code_usage_analyzer.py:16: in <module>\n    from scripts.run_code_usage_analysis import CodeUsageAnalyzer\nE   ModuleNotFoundError: No module named 'scripts.run_code_usage_analysis'\n_________ ERROR collecting tests/integration/test_complete_trading.py __________\nImportError while importing test module '/mnt/SSD/PYCHARMPRODJECT/BOT_AI_V3/tests/integration/test_complete_trading.py'.\nHint: make sure your test modules/packages have valid Python names.\nTraceback:\nvenv/lib/python3.12/site-packages/_pytest/python.py:498: in importtestmodule\n    mod = import_path(\nvenv/lib/python3.12/site-packages/_pytest/pathlib.py:587: in import_path\n    importlib.import_module(module_name)\n/usr/lib/python3.12/importlib/__init__.py:90: in import_module\n    return _bootstrap._gcd_import(name[level:], package, level)\n           ^^^^^^^^^^^^^^^^^^^^^^^^^^^^^^^^^^^^^^^^^^^^^^^^^^^^\n<frozen importlib._bootstrap>:1387: in _gcd_import\n    ???\n<frozen importlib._bootstrap>:1360: in _find_and_load\n    ???\n<frozen importlib._bootstrap>:1331: in _find_and_load_unlocked\n    ???\n<frozen importlib._bootstrap>:935: in _load_unlocked\n    ???\nvenv/lib/python3.12/site-packages/_pytest/assertion/rewrite.py:186: in exec_module\n    exec(co, module.__dict__)\ntests/integration/test_complete_trading.py:21: in <module>\n    from exchanges.base.order_types import OrderRequest, OrderSide, OrderType\nE   ModuleNotFoundError: No module named 'exchanges.base'\n=========================== short test summary info ============================\nERROR tests/analysis/test_code_analyzer_validation.py\nERROR tests/analysis/test_code_usage_analyzer.py\nERROR tests/integration/test_complete_trading.py\n!!!!!!!!!!!!!!!!!!!!!!!!!! stopping after 3 failures !!!!!!!!!!!!!!!!!!!!!!!!!!!\n========================= 1 warning, 3 errors in 0.14s =========================\n",
    "errors": "",
    "tests_collected": 0,
    "tests_passed": 0,
    "tests_failed": 0,
    "coverage_run": false
  },
  "coverage_analysis": {
    "success": false,
    "output": "============================= test session starts ==============================\nplatform linux -- Python 3.12.3, pytest-8.4.1, pluggy-1.6.0\nrootdir: /mnt/SSD/PYCHARMPRODJECT/BOT_AI_V3\nconfigfile: pytest.ini\nplugins: cov-6.2.1, anyio-4.9.0, asyncio-1.1.0\nasyncio: mode=Mode.AUTO, asyncio_default_fixture_loop_scope=None, asyncio_default_test_loop_scope=function\ncollected 22 items / 3 errors\nrun-last-failure: None\n\n==================================== ERRORS ====================================\n_______ ERROR collecting tests/analysis/test_code_analyzer_validation.py _______\nImportError while importing test module '/mnt/SSD/PYCHARMPRODJECT/BOT_AI_V3/tests/analysis/test_code_analyzer_validation.py'.\nHint: make sure your test modules/packages have valid Python names.\nTraceback:\n/usr/lib/python3.12/importlib/__init__.py:90: in import_module\n    return _bootstrap._gcd_import(name[level:], package, level)\n           ^^^^^^^^^^^^^^^^^^^^^^^^^^^^^^^^^^^^^^^^^^^^^^^^^^^^\ntests/analysis/test_code_analyzer_validation.py:15: in <module>\n    from scripts.run_code_usage_analysis import CodeUsageAnalyzer\nE   ModuleNotFoundError: No module named 'scripts.run_code_usage_analysis'\n_________ ERROR collecting tests/analysis/test_code_usage_analyzer.py __________\nImportError while importing test module '/mnt/SSD/PYCHARMPRODJECT/BOT_AI_V3/tests/analysis/test_code_usage_analyzer.py'.\nHint: make sure your test modules/packages have valid Python names.\nTraceback:\n/usr/lib/python3.12/importlib/__init__.py:90: in import_module\n    return _bootstrap._gcd_import(name[level:], package, level)\n           ^^^^^^^^^^^^^^^^^^^^^^^^^^^^^^^^^^^^^^^^^^^^^^^^^^^^\ntests/analysis/test_code_usage_analyzer.py:16: in <module>\n    from scripts.run_code_usage_analysis import CodeUsageAnalyzer\nE   ModuleNotFoundError: No module named 'scripts.run_code_usage_analysis'\n_________ ERROR collecting tests/integration/test_complete_trading.py __________\nImportError while importing test module '/mnt/SSD/PYCHARMPRODJECT/BOT_AI_V3/tests/integration/test_complete_trading.py'.\nHint: make sure your test modules/packages have valid Python names.\nTraceback:\n/usr/lib/python3.12/importlib/__init__.py:90: in import_module\n    return _bootstrap._gcd_import(name[level:], package, level)\n           ^^^^^^^^^^^^^^^^^^^^^^^^^^^^^^^^^^^^^^^^^^^^^^^^^^^^\ntests/integration/test_complete_trading.py:21: in <module>\n    from exchanges.base.order_types import OrderRequest, OrderSide, OrderType\nE   ModuleNotFoundError: No module named 'exchanges.base'\n=========================== short test summary info ============================\nERROR tests/analysis/test_code_analyzer_validation.py\nERROR tests/analysis/test_code_usage_analyzer.py\nERROR tests/integration/test_complete_trading.py\n!!!!!!!!!!!!!!!!!!!!!!!!!! stopping after 3 failures !!!!!!!!!!!!!!!!!!!!!!!!!!!\n========================= 1 warning, 3 errors in 0.13s =========================\n",
    "errors": "",
    "coverage_data": {},
    "coverage_percentage": 0,
    "html_report": "/mnt/SSD/PYCHARMPRODJECT/BOT_AI_V3/htmlcov/index.html"
  },
  "total_duration": 3.600722312927246,
  "total_components": 4,
  "successful_components": 0,
  "overall_success_rate": 0.0,
  "end_time": 1755686352.2467568
}