{
  "timestamp": "2025-08-20T14:30:22.916514",
  "project": "/mnt/SSD/PYCHARMPRODJECT/BOT_AI_V3",
  "stats": {
    "total_tests": 0,
    "passed_tests": 0,
    "failed_tests": 0,
    "coverage_percent": 0.0,
    "execution_time": 2.261456251144409,
    "errors": [],
    "warnings": []
  },
  "components": {
    "dynamic_sltp_comprehensive": {
      "name": "Complete Dynamic SL/TP Suite",
      "start_time": "2025-08-20T14:30:20.655024",
      "status": "success",
      "output": "============================= test session starts ==============================\nplatform linux -- Python 3.12.3, pytest-8.4.1, pluggy-1.6.0 -- /mnt/SSD/PYCHARMPRODJECT/BOT_AI_V3/venv/bin/python3\ncachedir: .pytest_cache\nrootdir: /mnt/SSD/PYCHARMPRODJECT/BOT_AI_V3\nconfigfile: pytest.ini\nplugins: cov-6.2.1, anyio-4.9.0, asyncio-1.1.0\nasyncio: mode=Mode.AUTO, asyncio_default_fixture_loop_scope=None, asyncio_default_test_loop_scope=function\ncollecting ... collected 14 items / 2 errors / 14 deselected / 0 selected\nrun-last-failure: 151 known failures not in selected tests\n\n==================================== ERRORS ====================================\n_____ ERROR collecting tests/integration/test_dynamic_sltp_integration.py ______\nImportError while importing test module '/mnt/SSD/PYCHARMPRODJECT/BOT_AI_V3/tests/integration/test_dynamic_sltp_integration.py'.\nHint: make sure your test modules/packages have valid Python names.\nTraceback:\nvenv/lib/python3.12/site-packages/_pytest/python.py:498: in importtestmodule\n    mod = import_path(\nvenv/lib/python3.12/site-packages/_pytest/pathlib.py:587: in import_path\n    importlib.import_module(module_name)\n/usr/lib/python3.12/importlib/__init__.py:90: in import_module\n    return _bootstrap._gcd_import(name[level:], package, level)\n           ^^^^^^^^^^^^^^^^^^^^^^^^^^^^^^^^^^^^^^^^^^^^^^^^^^^^\n<frozen importlib._bootstrap>:1387: in _gcd_import\n    ???\n<frozen importlib._bootstrap>:1360: in _find_and_load\n    ???\n<frozen importlib._bootstrap>:1331: in _find_and_load_unlocked\n    ???\n<frozen importlib._bootstrap>:935: in _load_unlocked\n    ???\nvenv/lib/python3.12/site-packages/_pytest/assertion/rewrite.py:186: in exec_module\n    exec(co, module.__dict__)\ntests/integration/test_dynamic_sltp_integration.py:14: in <module>\n    from ml.ml_signal_processor import MLSignalProcessor\nml/ml_signal_processor.py:22: in <module>\n    from ml.ml_manager import MLManager\nml/ml_manager.py:19: in <module>\n    from ml.logic.feature_engineering_production import (  # Production \u0432\u0435\u0440\u0441\u0438\u044f \u0438\u0437 \u043e\u0431\u0443\u0447\u0430\u044e\u0449\u0435\u0433\u043e \u0444\u0430\u0439\u043b\u0430\nml/logic/__init__.py:6: in <module>\n    from .feature_engineering_production import ProductionFeatureEngineer as FeatureEngineer\nE   ModuleNotFoundError: No module named 'ml.logic.feature_engineering_production'\n_________ ERROR collecting tests/integration/test_dynamic_sltp_e2e.py __________\nImportError while importing test module '/mnt/SSD/PYCHARMPRODJECT/BOT_AI_V3/tests/integration/test_dynamic_sltp_e2e.py'.\nHint: make sure your test modules/packages have valid Python names.\nTraceback:\nvenv/lib/python3.12/site-packages/_pytest/python.py:498: in importtestmodule\n    mod = import_path(\nvenv/lib/python3.12/site-packages/_pytest/pathlib.py:587: in import_path\n    importlib.import_module(module_name)\n/usr/lib/python3.12/importlib/__init__.py:90: in import_module\n    return _bootstrap._gcd_import(name[level:], package, level)\n           ^^^^^^^^^^^^^^^^^^^^^^^^^^^^^^^^^^^^^^^^^^^^^^^^^^^^\n<frozen importlib._bootstrap>:1387: in _gcd_import\n    ???\n<frozen importlib._bootstrap>:1360: in _find_and_load\n    ???\n<frozen importlib._bootstrap>:1331: in _find_and_load_unlocked\n    ???\n<frozen importlib._bootstrap>:935: in _load_unlocked\n    ???\nvenv/lib/python3.12/site-packages/_pytest/assertion/rewrite.py:186: in exec_module\n    exec(co, module.__dict__)\ntests/integration/test_dynamic_sltp_e2e.py:15: in <module>\n    from ml.ml_signal_processor import MLSignalProcessor\nml/ml_signal_processor.py:22: in <module>\n    from ml.ml_manager import MLManager\nml/ml_manager.py:19: in <module>\n    from ml.logic.feature_engineering_production import (  # Production \u0432\u0435\u0440\u0441\u0438\u044f \u0438\u0437 \u043e\u0431\u0443\u0447\u0430\u044e\u0449\u0435\u0433\u043e \u0444\u0430\u0439\u043b\u0430\nml/logic/__init__.py:6: in <module>\n    from .feature_engineering_production import ProductionFeatureEngineer as FeatureEngineer\nE   ModuleNotFoundError: No module named 'ml.logic.feature_engineering_production'\n=============================== warnings summary ===============================\ndatabase/connections/postgres.py:37\n  /mnt/SSD/PYCHARMPRODJECT/BOT_AI_V3/database/connections/postgres.py:37: MovedIn20Warning: The ``declarative_base()`` function is now available as sqlalchemy.orm.declarative_base(). (deprecated since: 2.0) (Background on SQLAlchemy 2.0 at: https://sqlalche.me/e/b8d9)\n    Base = declarative_base()\n\ndatabase/models/ml_predictions.py:21\n  /mnt/SSD/PYCHARMPRODJECT/BOT_AI_V3/database/models/ml_predictions.py:21: MovedIn20Warning: The ``declarative_base()`` function is now available as sqlalchemy.orm.declarative_base(). (deprecated since: 2.0) (Background on SQLAlchemy 2.0 at: https://sqlalche.me/e/b8d9)\n    Base = declarative_base()\n\n-- Docs: https://docs.pytest.org/en/stable/how-to/capture-warnings.html\n=========================== short test summary info ============================\nERROR tests/integration/test_dynamic_sltp_integration.py\nERROR tests/integration/test_dynamic_sltp_e2e.py\n!!!!!!!!!!!!!!!!!!! Interrupted: 2 errors during collection !!!!!!!!!!!!!!!!!!!!\n================= 14 deselected, 2 warnings, 2 errors in 0.30s =================\n",
      "error": "",
      "execution_time": 1.7607028484344482,
      "end_time": "2025-08-20T14:30:22.415731"
    }
  },
  "coverage": {}
}